<testsuite errors="5" failures="0" name="Django Project Tests" skips="0" tests="17" time="427.908"><testcase classname="__main__.TestAdminSQLite" name="test_add_del" time="26.089038" /><testcase classname="__main__.TestAdminSQLite" name="test_add_modif" time="14.730016" /><testcase classname="__main__.TestAdminSQLite" name="test_add_read" time="17.285218" /><testcase classname="__main__.TestAdminSQLite" name="test_archive" time="41.359059" /><testcase classname="__main__.TestAdminSQLite" name="test_extra" time="13.718053" /><testcase classname="__main__.TestAdminSQLite" name="test_migration" time="133.782591"><error message="Direct assignment to the forward side of a many-to-many set is prohibited. Use permissions.set() instead." type="builtins.TypeError">Traceback (most recent call last):
  File "/home/dev/Lucterios2/lct-core/lucterios/install/admin_test.py", line 297, in test_migration
    mirg.restore()
  File "/home/dev/Lucterios2/lct-core/lucterios/install/lucterios_migration.py", line 287, in restore
    self.run_module_migrate(modulename)
  File "/home/dev/Lucterios2/lct-core/lucterios/install/lucterios_migration.py", line 268, in run_module_migrate
    migrate_class(self.old_db).run()
  File "/home/dev/Lucterios2/lct-core/lucterios/CORE/from_v1.py", line 235, in run
    self._groups()
  File "/home/dev/Lucterios2/lct-core/lucterios/CORE/from_v1.py", line 200, in _groups
    id__in=premission_ref)
  File "/usr/local/lib/python3.5/site-packages/django/db/models/fields/related_descriptors.py", line 509, in __set__
    % self._get_set_deprecation_msg_params(),
TypeError: Direct assignment to the forward side of a many-to-many set is prohibited. Use permissions.set() instead.
</error></testcase><testcase classname="__main__.TestAdminSQLite" name="test_security" time="15.025581" /><testcase classname="__main__.TestAdminMySQL" name="test_add_read" time="0.357897"><error message="(1049, &quot;Unknown database 'testv2'&quot;)" type="django.db.utils.OperationalError">Traceback (most recent call last):
  File "/usr/local/lib/python3.5/site-packages/django/db/backends/base/base.py", line 216, in ensure_connection
    self.connect()
  File "/usr/local/lib/python3.5/site-packages/django/db/backends/base/base.py", line 194, in connect
    self.connection = self.get_new_connection(conn_params)
  File "/usr/local/lib/python3.5/site-packages/django/db/backends/mysql/base.py", line 236, in get_new_connection
    return Database.connect(**conn_params)
  File "/usr/local/lib/python3.5/site-packages/MySQLdb/__init__.py", line 85, in Connect
    return Connection(*args, **kwargs)
  File "/usr/local/lib/python3.5/site-packages/MySQLdb/connections.py", line 204, in __init__
    super(Connection, self).__init__(*args, **kwargs2)
_mysql_exceptions.OperationalError: (1049, "Unknown database 'testv2'")

The above exception was the direct cause of the following exception:

Traceback (most recent call last):
  File "/home/dev/Lucterios2/lct-core/lucterios/install/admin_test.py", line 333, in test_add_read
    inst.add()
  File "/home/dev/Lucterios2/lct-core/lucterios/install/lucterios_admin.py", line 633, in add
    self.refresh()
  File "/home/dev/Lucterios2/lct-core/lucterios/install/lucterios_admin.py", line 697, in refresh
    call_command('migrate', stdout=sys.stdout)
  File "/usr/local/lib/python3.5/site-packages/django/core/management/__init__.py", line 141, in call_command
    return command.execute(*args, **defaults)
  File "/usr/local/lib/python3.5/site-packages/django/core/management/base.py", line 335, in execute
    output = self.handle(*args, **options)
  File "/usr/local/lib/python3.5/site-packages/django/core/management/commands/migrate.py", line 79, in handle
    executor = MigrationExecutor(connection, self.migration_progress_callback)
  File "/usr/local/lib/python3.5/site-packages/django/db/migrations/executor.py", line 18, in __init__
    self.loader = MigrationLoader(self.connection)
  File "/usr/local/lib/python3.5/site-packages/django/db/migrations/loader.py", line 49, in __init__
    self.build_graph()
  File "/usr/local/lib/python3.5/site-packages/django/db/migrations/loader.py", line 206, in build_graph
    self.applied_migrations = recorder.applied_migrations()
  File "/usr/local/lib/python3.5/site-packages/django/db/migrations/recorder.py", line 61, in applied_migrations
    if self.has_table():
  File "/usr/local/lib/python3.5/site-packages/django/db/migrations/recorder.py", line 44, in has_table
    return self.Migration._meta.db_table in self.connection.introspection.table_names(self.connection.cursor())
  File "/usr/local/lib/python3.5/site-packages/django/db/backends/base/base.py", line 255, in cursor
    return self._cursor()
  File "/usr/local/lib/python3.5/site-packages/django/db/backends/base/base.py", line 232, in _cursor
    self.ensure_connection()
  File "/usr/local/lib/python3.5/site-packages/django/db/backends/base/base.py", line 216, in ensure_connection
    self.connect()
  File "/usr/local/lib/python3.5/site-packages/django/db/utils.py", line 89, in __exit__
    raise dj_exc_value.with_traceback(traceback) from exc_value
  File "/usr/local/lib/python3.5/site-packages/django/db/backends/base/base.py", line 216, in ensure_connection
    self.connect()
  File "/usr/local/lib/python3.5/site-packages/django/db/backends/base/base.py", line 194, in connect
    self.connection = self.get_new_connection(conn_params)
  File "/usr/local/lib/python3.5/site-packages/django/db/backends/mysql/base.py", line 236, in get_new_connection
    return Database.connect(**conn_params)
  File "/usr/local/lib/python3.5/site-packages/MySQLdb/__init__.py", line 85, in Connect
    return Connection(*args, **kwargs)
  File "/usr/local/lib/python3.5/site-packages/MySQLdb/connections.py", line 204, in __init__
    super(Connection, self).__init__(*args, **kwargs2)
django.db.utils.OperationalError: (1049, "Unknown database 'testv2'")
</error></testcase><testcase classname="__main__.TestAdminMySQL" name="test_archive" time="13.349174"><error message="(1049, &quot;Unknown database 'testv2'&quot;)" type="django.db.utils.OperationalError">Traceback (most recent call last):
  File "/usr/local/lib/python3.5/site-packages/django/db/backends/base/base.py", line 216, in ensure_connection
    self.connect()
  File "/usr/local/lib/python3.5/site-packages/django/db/backends/base/base.py", line 194, in connect
    self.connection = self.get_new_connection(conn_params)
  File "/usr/local/lib/python3.5/site-packages/django/db/backends/mysql/base.py", line 236, in get_new_connection
    return Database.connect(**conn_params)
  File "/usr/local/lib/python3.5/site-packages/MySQLdb/__init__.py", line 85, in Connect
    return Connection(*args, **kwargs)
  File "/usr/local/lib/python3.5/site-packages/MySQLdb/connections.py", line 204, in __init__
    super(Connection, self).__init__(*args, **kwargs2)
_mysql_exceptions.OperationalError: (1049, "Unknown database 'testv2'")

The above exception was the direct cause of the following exception:

Traceback (most recent call last):
  File "/home/dev/Lucterios2/lct-core/lucterios/install/admin_test.py", line 371, in test_archive
    inst.add()
  File "/home/dev/Lucterios2/lct-core/lucterios/install/lucterios_admin.py", line 633, in add
    self.refresh()
  File "/home/dev/Lucterios2/lct-core/lucterios/install/lucterios_admin.py", line 697, in refresh
    call_command('migrate', stdout=sys.stdout)
  File "/usr/local/lib/python3.5/site-packages/django/core/management/__init__.py", line 141, in call_command
    return command.execute(*args, **defaults)
  File "/usr/local/lib/python3.5/site-packages/django/core/management/base.py", line 335, in execute
    output = self.handle(*args, **options)
  File "/usr/local/lib/python3.5/site-packages/django/core/management/commands/migrate.py", line 79, in handle
    executor = MigrationExecutor(connection, self.migration_progress_callback)
  File "/usr/local/lib/python3.5/site-packages/django/db/migrations/executor.py", line 18, in __init__
    self.loader = MigrationLoader(self.connection)
  File "/usr/local/lib/python3.5/site-packages/django/db/migrations/loader.py", line 49, in __init__
    self.build_graph()
  File "/usr/local/lib/python3.5/site-packages/django/db/migrations/loader.py", line 206, in build_graph
    self.applied_migrations = recorder.applied_migrations()
  File "/usr/local/lib/python3.5/site-packages/django/db/migrations/recorder.py", line 61, in applied_migrations
    if self.has_table():
  File "/usr/local/lib/python3.5/site-packages/django/db/migrations/recorder.py", line 44, in has_table
    return self.Migration._meta.db_table in self.connection.introspection.table_names(self.connection.cursor())
  File "/usr/local/lib/python3.5/site-packages/django/db/backends/base/base.py", line 255, in cursor
    return self._cursor()
  File "/usr/local/lib/python3.5/site-packages/django/db/backends/base/base.py", line 232, in _cursor
    self.ensure_connection()
  File "/usr/local/lib/python3.5/site-packages/django/db/backends/base/base.py", line 216, in ensure_connection
    self.connect()
  File "/usr/local/lib/python3.5/site-packages/django/db/utils.py", line 89, in __exit__
    raise dj_exc_value.with_traceback(traceback) from exc_value
  File "/usr/local/lib/python3.5/site-packages/django/db/backends/base/base.py", line 216, in ensure_connection
    self.connect()
  File "/usr/local/lib/python3.5/site-packages/django/db/backends/base/base.py", line 194, in connect
    self.connection = self.get_new_connection(conn_params)
  File "/usr/local/lib/python3.5/site-packages/django/db/backends/mysql/base.py", line 236, in get_new_connection
    return Database.connect(**conn_params)
  File "/usr/local/lib/python3.5/site-packages/MySQLdb/__init__.py", line 85, in Connect
    return Connection(*args, **kwargs)
  File "/usr/local/lib/python3.5/site-packages/MySQLdb/connections.py", line 204, in __init__
    super(Connection, self).__init__(*args, **kwargs2)
django.db.utils.OperationalError: (1049, "Unknown database 'testv2'")
</error></testcase><testcase classname="__main__.TestAdminMySQL" name="test_migration" time="0.291963"><error message="(1049, &quot;Unknown database 'testv2'&quot;)" type="django.db.utils.OperationalError">Traceback (most recent call last):
  File "/usr/local/lib/python3.5/site-packages/django/db/backends/base/base.py", line 216, in ensure_connection
    self.connect()
  File "/usr/local/lib/python3.5/site-packages/django/db/backends/base/base.py", line 194, in connect
    self.connection = self.get_new_connection(conn_params)
  File "/usr/local/lib/python3.5/site-packages/django/db/backends/mysql/base.py", line 236, in get_new_connection
    return Database.connect(**conn_params)
  File "/usr/local/lib/python3.5/site-packages/MySQLdb/__init__.py", line 85, in Connect
    return Connection(*args, **kwargs)
  File "/usr/local/lib/python3.5/site-packages/MySQLdb/connections.py", line 204, in __init__
    super(Connection, self).__init__(*args, **kwargs2)
_mysql_exceptions.OperationalError: (1049, "Unknown database 'testv2'")

The above exception was the direct cause of the following exception:

Traceback (most recent call last):
  File "/home/dev/Lucterios2/lct-core/lucterios/install/admin_test.py", line 381, in test_migration
    inst.add()
  File "/home/dev/Lucterios2/lct-core/lucterios/install/lucterios_admin.py", line 633, in add
    self.refresh()
  File "/home/dev/Lucterios2/lct-core/lucterios/install/lucterios_admin.py", line 697, in refresh
    call_command('migrate', stdout=sys.stdout)
  File "/usr/local/lib/python3.5/site-packages/django/core/management/__init__.py", line 141, in call_command
    return command.execute(*args, **defaults)
  File "/usr/local/lib/python3.5/site-packages/django/core/management/base.py", line 335, in execute
    output = self.handle(*args, **options)
  File "/usr/local/lib/python3.5/site-packages/django/core/management/commands/migrate.py", line 79, in handle
    executor = MigrationExecutor(connection, self.migration_progress_callback)
  File "/usr/local/lib/python3.5/site-packages/django/db/migrations/executor.py", line 18, in __init__
    self.loader = MigrationLoader(self.connection)
  File "/usr/local/lib/python3.5/site-packages/django/db/migrations/loader.py", line 49, in __init__
    self.build_graph()
  File "/usr/local/lib/python3.5/site-packages/django/db/migrations/loader.py", line 206, in build_graph
    self.applied_migrations = recorder.applied_migrations()
  File "/usr/local/lib/python3.5/site-packages/django/db/migrations/recorder.py", line 61, in applied_migrations
    if self.has_table():
  File "/usr/local/lib/python3.5/site-packages/django/db/migrations/recorder.py", line 44, in has_table
    return self.Migration._meta.db_table in self.connection.introspection.table_names(self.connection.cursor())
  File "/usr/local/lib/python3.5/site-packages/django/db/backends/base/base.py", line 255, in cursor
    return self._cursor()
  File "/usr/local/lib/python3.5/site-packages/django/db/backends/base/base.py", line 232, in _cursor
    self.ensure_connection()
  File "/usr/local/lib/python3.5/site-packages/django/db/backends/base/base.py", line 216, in ensure_connection
    self.connect()
  File "/usr/local/lib/python3.5/site-packages/django/db/utils.py", line 89, in __exit__
    raise dj_exc_value.with_traceback(traceback) from exc_value
  File "/usr/local/lib/python3.5/site-packages/django/db/backends/base/base.py", line 216, in ensure_connection
    self.connect()
  File "/usr/local/lib/python3.5/site-packages/django/db/backends/base/base.py", line 194, in connect
    self.connection = self.get_new_connection(conn_params)
  File "/usr/local/lib/python3.5/site-packages/django/db/backends/mysql/base.py", line 236, in get_new_connection
    return Database.connect(**conn_params)
  File "/usr/local/lib/python3.5/site-packages/MySQLdb/__init__.py", line 85, in Connect
    return Connection(*args, **kwargs)
  File "/usr/local/lib/python3.5/site-packages/MySQLdb/connections.py", line 204, in __init__
    super(Connection, self).__init__(*args, **kwargs2)
django.db.utils.OperationalError: (1049, "Unknown database 'testv2'")
</error></testcase><testcase classname="__main__.TestAdminPostGreSQL" name="test_add_read" time="7.944669" /><testcase classname="__main__.TestAdminPostGreSQL" name="test_archive" time="22.904532" /><testcase classname="__main__.TestAdminPostGreSQL" name="test_migration" time="110.880362"><error message="Direct assignment to the forward side of a many-to-many set is prohibited. Use permissions.set() instead." type="builtins.TypeError">Traceback (most recent call last):
  File "/home/dev/Lucterios2/lct-core/lucterios/install/admin_test.py", line 480, in test_migration
    mirg.restore()
  File "/home/dev/Lucterios2/lct-core/lucterios/install/lucterios_migration.py", line 287, in restore
    self.run_module_migrate(modulename)
  File "/home/dev/Lucterios2/lct-core/lucterios/install/lucterios_migration.py", line 268, in run_module_migrate
    migrate_class(self.old_db).run()
  File "/home/dev/Lucterios2/lct-core/lucterios/CORE/from_v1.py", line 235, in run
    self._groups()
  File "/home/dev/Lucterios2/lct-core/lucterios/CORE/from_v1.py", line 200, in _groups
    id__in=premission_ref)
  File "/usr/local/lib/python3.5/site-packages/django/db/models/fields/related_descriptors.py", line 509, in __set__
    % self._get_set_deprecation_msg_params(),
TypeError: Direct assignment to the forward side of a many-to-many set is prohibited. Use permissions.set() instead.
</error></testcase><testcase classname="__main__.TestGlobal" name="test_check" time="10.167386" /><testcase classname="__main__.TestGlobal" name="test_check_pypi" time="0.001346" /><testcase classname="__main__.TestGlobal" name="test_installed" time="0.002907" /><testcase classname="__main__.TestGlobal" name="test_refresh_all" time="0.000323" /></testsuite>